Workbook

Sheet Strength
A2: Competitive strength
A3: Draft competitive strength: scale plus client/partner network. ETF positioning remains a separate diagnostic.
A5: Universe status | B5: Cap-eligible issuers | C5: Revenue-ready issuers | D5: Eligible cap USD bn | E5: Relevant revenue USD bn | G5: Passive funds | H5: Active funds | I5: Passive AUM USD bn | J5: Active AUM USD bn
A6: =IF(Rules!$B$7="Not selected","Choose research scope",IF(Rules!$B$15<>"Yes","Confirm issuer universe",IF(B6<Rules!$B$12,"Too few comparable issuers",IF(B6<>C6,"Revenue inputs incomplete",IF(E6<=0,"Revenue denominator missing",IF(OR(Rules!$B$13<0,Rules!$B$14<0,ABS(SUM(Rules!$B$13:$B$14)-1)>0.000001),"Check score weights","Ready")))))) -> Choose research scope | B6: =COUNTIFS(Companies!$R$6:$R$55,1) -> 0 | C6: =COUNTIFS(Companies!$S$6:$S$55,1) -> 0 | D6: =SUMIFS(Companies!$I$6:$I$55,Companies!$R$6:$R$55,1) -> 0 | E6: =SUMIFS(Companies!$K$6:$K$55,Companies!$S$6:$S$55,1) -> 0 | G6: =COUNTIFS(ETFs!$K$6:$K$25,1,ETFs!$D$6:$D$25,"Passive") -> 0 | H6: =COUNTIFS(ETFs!$K$6:$K$25,1,ETFs!$D$6:$D$25,"Active") -> 0 | I6: =SUMIFS(ETFs!$G$6:$G$25,ETFs!$K$6:$K$25,1,ETFs!$D$6:$D$25,"Passive") -> 0 | J6: =SUMIFS(ETFs!$G$6:$G$25,ETFs!$K$6:$K$25,1,ETFs!$D$6:$D$25,"Active") -> 0
A9: Issuer ID | B9: Company | C9: Cap rank | D9: Cap share | E9: Revenue share | F9: Cap/revenue share ratio | G9: Cap percentile | H9: Revenue percentile | I9: Scale score /100 | J9: Competitor count | K9: Larger competitors | L9: Cap / avg competitor cap | M9: Passive pairs ready | N9: Active pairs ready | O9: Passive ETF weight | P9: Active ETF weight | Q9: Passive ownership proxy | R9: Active ownership proxy | S9: ETF coverage | T9: Network score /100 | U9: Competitive strength /100 | V9: Combined status
A10: =IF(Companies!R6=1,Companies!A6,"") | B10: =IF(A10="","",Companies!C6) | C10: =IF(A10="","",1+COUNTIFS(Companies!$R$6:$R$55,1,Companies!$I$6:$I$55,">"&Companies!I6)) | D10: =IF(A10="","",Companies!I6/$D$6) | E10: =IF(A10="","",IF($A$6<>"Ready","n.a.",Companies!K6/$E$6)) | F10: =IF(A10="","",IF(OR($A$6<>"Ready",E10=0),"n.a.",D10/E10)) | G10: =IF(A10="","",IF($B$6<Rules!$B$12,"n.a.",100*(COUNTIFS(Companies!$R$6:$R$55,1,Companies!$I$6:$I$55,"<"&Companies!I6)+0.5*(COUNTIFS(Companies!$R$6:$R$55,1,Companies!$I$6:$I$55,Companies!I6)-1))/($B$6-1))) | H10: =IF(A10="","",IF($A$6<>"Ready","n.a.",100*(COUNTIFS(Companies!$S$6:$S$55,1,Companies!$K$6:$K$55,"<"&Companies!K6)+0.5*(COUNTIFS(Companies!$S$6:$S$55,1,Companies!$K$6:$K$55,Companies!K6)-1))/($C$6-1))) | I10: =IF(A10="","",IF($A$6<>"Ready","n.a.",Rules!$B$13*H10+Rules!$B$14*G10)) | J10: =IF(A10="","",$B$6-1) | K10: =IF(A10="","",C10-1) | L10: =IF(A10="","",IF(OR($B$6<2,$D$6<=Companies!I6),"n.a.",Companies!I6/(($D$6-Companies!I6)/($B$6-1)))) | M10: =IF(A10="","",COUNTIFS(Holdings!$A$6:$A$205,A10,Holdings!$H$6:$H$205,"Passive",Holdings!$K$6:$K$205,1)) | N10: =IF(A10="","",COUNTIFS(Holdings!$A$6:$A$205,A10,Holdings!$H$6:$H$205,"Active",Holdings!$K$6:$K$205,1)) | O10: =IF(A10="","",IF(OR($G$6=0,M10<>$G$6),"n.a.",SUMIFS(Holdings!$D$6:$D$205,Holdings!$A$6:$A$205,A10,Holdings!$H$6:$H$205,"Passive",Holdings!$K$6:$K$205,1)/$I$6)) | P10: =IF(A10="","",IF(OR($H$6=0,N10<>$H$6),"n.a.",SUMIFS(Holdings!$D$6:$D$205,Holdings!$A$6:$A$205,A10,Holdings!$H$6:$H$205,"Active",Holdings!$K$6:$K$205,1)/$J$6)) | Q10: =IF(A10="","",IF(OR($G$6=0,M10<>$G$6),"n.a.",SUMIFS(Holdings!$D$6:$D$205,Holdings!$A$6:$A$205,A10,Holdings!$H$6:$H$205,"Passive",Holdings!$K$6:$K$205,1)/Companies!I6)) | R10: =IF(A10="","",IF(OR($H$6=0,N10<>$H$6),"n.a.",SUMIFS(Holdings!$D$6:$D$205,Holdings!$A$6:$A$205,A10,Holdings!$H$6:$H$205,"Active",Holdings!$K$6:$K$205,1)/Companies!I6)) | S10: =IF(A10="","",IF($G$6+$H$6=0,"No ETF panel",IF(M10+N10=$G$6+$H$6,"Complete selected panel","Missing ETF pairs"))) | T10: {=IF(A10="","",IFNA(INDEX(Network!$L$14:$L$63,MATCH(A10,Network!$A$14:$A$63,0)),"n.a."))} | U10: =IF(A10="","",IF(OR(OR(COUNT(Rules!$B$45:$B$46)<>2,MIN(Rules!$B$45:$B$46)<0,ABS(SUM(Rules!$B$45:$B$46)-1)>0.000001),AND(Rules!$B$45>0,NOT(ISNUMBER(I10))),AND(Rules!$B$46>0,NOT(ISNUMBER(T10)))),"n.a.",IF(Rules!$B$45=0,0,Rules!$B$45*I10)+IF(Rules!$B$46=0,0,Rules!$B$46*T10))) | V10: =IF(A10="","",IF(OR(COUNT(Rules!$B$45:$B$46)<>2,MIN(Rules!$B$45:$B$46)<0,ABS(SUM(Rules!$B$45:$B$46)-1)>0.000001),"Check combined weights",IF(AND(Rules!$B$45>0,NOT(ISNUMBER(I10))),"Scale score unavailable",IF(AND(Rules!$B$46>0,NOT(ISNUMBER(T10))),"Network review/score unavailable","Ready"))))
A11: =IF(Companies!R7=1,Companies!A7,"") | B11: =IF(A11="","",Companies!C7) | C11: =IF(A11="","",1+COUNTIFS(Companies!$R$6:$R$55,1,Companies!$I$6:$I$55,">"&Companies!I7)) | D11: =IF(A11="","",Companies!I7/$D$6) | E11: =IF(A11="","",IF($A$6<>"Ready","n.a.",Companies!K7/$E$6)) | F11: =IF(A11="","",IF(OR($A$6<>"Ready",E11=0),"n.a.",D11/E11)) | G11: =IF(A11="","",IF($B$6<Rules!$B$12,"n.a.",100*(COUNTIFS(Companies!$R$6:$R$55,1,Companies!$I$6:$I$55,"<"&Companies!I7)+0.5*(COUNTIFS(Companies!$R$6:$R$55,1,Companies!$I$6:$I$55,Companies!I7)-1))/($B$6-1))) | H11: =IF(A11="","",IF($A$6<>"Ready","n.a.",100*(COUNTIFS(Companies!$S$6:$S$55,1,Companies!$K$6:$K$55,"<"&Companies!K7)+0.5*(COUNTIFS(Companies!$S$6:$S$55,1,Companies!$K$6:$K$55,Companies!K7)-1))/($C$6-1))) | I11: =IF(A11="","",IF($A$6<>"Ready","n.a.",Rules!$B$13*H11+Rules!$B$14*G11)) | J11: =IF(A11="","",$B$6-1) | K11: =IF(A11="","",C11-1) | L11: =IF(A11="","",IF(OR($B$6<2,$D$6<=Companies!I7),"n.a.",Companies!I7/(($D$6-Companies!I7)/($B$6-1)))) | M11: =IF(A11="","",COUNTIFS(Holdings!$A$6:$A$205,A11,Holdings!$H$6:$H$205,"Passive",Holdings!$K$6:$K$205,1)) | N11: =IF(A11="","",COUNTIFS(Holdings!$A$6:$A$205,A11,Holdings!$H$6:$H$205,"Active",Holdings!$K$6:$K$205,1)) | O11: =IF(A11="","",IF(OR($G$6=0,M11<>$G$6),"n.a.",SUMIFS(Holdings!$D$6:$D$205,Holdings!$A$6:$A$205,A11,Holdings!$H$6:$H$205,"Passive",Holdings!$K$6:$K$205,1)/$I$6)) | P11: =IF(A11="","",IF(OR($H$6=0,N11<>$H$6),"n.a.",SUMIFS(Holdings!$D$6:$D$205,Holdings!$A$6:$A$205,A11,Holdings!$H$6:$H$205,"Active",Holdings!$K$6:$K$205,1)/$J$6)) | Q11: =IF(A11="","",IF(OR($G$6=0,M11<>$G$6),"n.a.",SUMIFS(Holdings!$D$6:$D$205,Holdings!$A$6:$A$205,A11,Holdings!$H$6:$H$205,"Passive",Holdings!$K$6:$K$205,1)/Companies!I7)) | R11: =IF(A11="","",IF(OR($H$6=0,N11<>$H$6),"n.a.",SUMIFS(Holdings!$D$6:$D$205,Holdings!$A$6:$A$205,A11,Holdings!$H$6:$H$205,"Active",Holdings!$K$6:$K$205,1)/Companies!I7)) | S11: =IF(A11="","",IF($G$6+$H$6=0,"No ETF panel",IF(M11+N11=$G$6+$H$6,"Complete selected panel","Missing ETF pairs"))) | T11: {=IF(A11="","",IFNA(INDEX(Network!$L$14:$L$63,MATCH(A11,Network!$A$14:$A$63,0)),"n.a."))} | U11: =IF(A11="","",IF(OR(OR(COUNT(Rules!$B$45:$B$46)<>2,MIN(Rules!$B$45:$B$46)<0,ABS(SUM(Rules!$B$45:$B$46)-1)>0.000001),AND(Rules!$B$45>0,NOT(ISNUMBER(I11))),AND(Rules!$B$46>0,NOT(ISNUMBER(T11)))),"n.a.",IF(Rules!$B$45=0,0,Rules!$B$45*I11)+IF(Rules!$B$46=0,0,Rules!$B$46*T11))) | V11: =IF(A11="","",IF(OR(COUNT(Rules!$B$45:$B$46)<>2,MIN(Rules!$B$45:$B$46)<0,ABS(SUM(Rules!$B$45:$B$46)-1)>0.000001),"Check combined weights",IF(AND(Rules!$B$45>0,NOT(ISNUMBER(I11))),"Scale score unavailable",IF(AND(Rules!$B$46>0,NOT(ISNUMBER(T11))),"Network review/score unavailable","Ready"))))
A12: =IF(Companies!R8=1,Companies!A8,"") | B12: =IF(A12="","",Companies!C8) | C12: =IF(A12="","",1+COUNTIFS(Companies!$R$6:$R$55,1,Companies!$I$6:$I$55,">"&Companies!I8)) | D12: =IF(A12="","",Companies!I8/$D$6) | E12: =IF(A12="","",IF($A$6<>"Ready","n.a.",Companies!K8/$E$6)) | F12: =IF(A12="","",IF(OR($A$6<>"Ready",E12=0),"n.a.",D12/E12)) | G12: =IF(A12="","",IF($B$6<Rules!$B$12,"n.a.",100*(COUNTIFS(Companies!$R$6:$R$55,1,Companies!$I$6:$I$55,"<"&Companies!I8)+0.5*(COUNTIFS(Companies!$R$6:$R$55,1,Companies!$I$6:$I$55,Companies!I8)-1))/($B$6-1))) | H12: =IF(A12="","",IF($A$6<>"Ready","n.a.",100*(COUNTIFS(Companies!$S$6:$S$55,1,Companies!$K$6:$K$55,"<"&Companies!K8)+0.5*(COUNTIFS(Companies!$S$6:$S$55,1,Companies!$K$6:$K$55,Companies!K8)-1))/($C$6-1))) | I12: =IF(A12="","",IF($A$6<>"Ready","n.a.",Rules!$B$13*H12+Rules!$B$14*G12)) | J12: =IF(A12="","",$B$6-1) | K12: =IF(A12="","",C12-1) | L12: =IF(A12="","",IF(OR($B$6<2,$D$6<=Companies!I8),"n.a.",Companies!I8/(($D$6-Companies!I8)/($B$6-1)))) | M12: =IF(A12="","",COUNTIFS(Holdings!$A$6:$A$205,A12,Holdings!$H$6:$H$205,"Passive",Holdings!$K$6:$K$205,1)) | N12: =IF(A12="","",COUNTIFS(Holdings!$A$6:$A$205,A12,Holdings!$H$6:$H$205,"Active",Holdings!$K$6:$K$205,1)) | O12: =IF(A12="","",IF(OR($G$6=0,M12<>$G$6),"n.a.",SUMIFS(Holdings!$D$6:$D$205,Holdings!$A$6:$A$205,A12,Holdings!$H$6:$H$205,"Passive",Holdings!$K$6:$K$205,1)/$I$6)) | P12: =IF(A12="","",IF(OR($H$6=0,N12<>$H$6),"n.a.",SUMIFS(Holdings!$D$6:$D$205,Holdings!$A$6:$A$205,A12,Holdings!$H$6:$H$205,"Active",Holdings!$K$6:$K$205,1)/$J$6)) | Q12: =IF(A12="","",IF(OR($G$6=0,M12<>$G$6),"n.a.",SUMIFS(Holdings!$D$6:$D$205,Holdings!$A$6:$A$205,A12,Holdings!$H$6:$H$205,"Passive",Holdings!$K$6:$K$205,1)/Companies!I8)) | R12: =IF(A12="","",IF(OR($H$6=0,N12<>$H$6),"n.a.",SUMIFS(Holdings!$D$6:$D$205,Holdings!$A$6:$A$205,A12,Holdings!$H$6:$H$205,"Active",Holdings!$K$6:$K$205,1)/Companies!I8)) | S12: =IF(A12="","",IF($G$6+$H$6=0,"No ETF panel",IF(M12+N12=$G$6+$H$6,"Complete selected panel","Missing ETF pairs"))) | T12: {=IF(A12="","",IFNA(INDEX(Network!$L$14:$L$63,MATCH(A12,Network!$A$14:$A$63,0)),"n.a."))} | U12: =IF(A12="","",IF(OR(OR(COUNT(Rules!$B$45:$B$46)<>2,MIN(Rules!$B$45:$B$46)<0,ABS(SUM(Rules!$B$45:$B$46)-1)>0.000001),AND(Rules!$B$45>0,NOT(ISNUMBER(I12))),AND(Rules!$B$46>0,NOT(ISNUMBER(T12)))),"n.a.",IF(Rules!$B$45=0,0,Rules!$B$45*I12)+IF(Rules!$B$46=0,0,Rules!$B$46*T12))) | V12: =IF(A12="","",IF(OR(COUNT(Rules!$B$45:$B$46)<>2,MIN(Rules!$B$45:$B$46)<0,ABS(SUM(Rules!$B$45:$B$46)-1)>0.000001),"Check combined weights",IF(AND(Rules!$B$45>0,NOT(ISNUMBER(I12))),"Scale score unavailable",IF(AND(Rules!$B$46>0,NOT(ISNUMBER(T12))),"Network review/score unavailable","Ready"))))
A13: =IF(Companies!R9=1,Companies!A9,"") | B13: =IF(A13="","",Companies!C9) | C13: =IF(A13="","",1+COUNTIFS(Companies!$R$6:$R$55,1,Companies!$I$6:$I$55,">"&Companies!I9)) | D13: =IF(A13="","",Companies!I9/$D$6) | E13: =IF(A13="","",IF($A$6<>"Ready","n.a.",Companies!K9/$E$6)) | F13: =IF(A13="","",IF(OR($A$6<>"Ready",E13=0),"n.a.",D13/E13)) | G13: =IF(A13="","",IF($B$6<Rules!$B$12,"n.a.",100*(COUNTIFS(Companies!$R$6:$R$55,1,Companies!$I$6:$I$55,"<"&Companies!I9)+0.5*(COUNTIFS(Companies!$R$6:$R$55,1,Companies!$I$6:$I$55,Companies!I9)-1))/($B$6-1))) | H13: =IF(A13="","",IF($A$6<>"Ready","n.a.",100*(COUNTIFS(Companies!$S$6:$S$55,1,Companies!$K$6:$K$55,"<"&Companies!K9)+0.5*(COUNTIFS(Companies!$S$6:$S$55,1,Companies!$K$6:$K$55,Companies!K9)-1))/($C$6-1))) | I13: =IF(A13="","",IF($A$6<>"Ready","n.a.",Rules!$B$13*H13+Rules!$B$14*G13)) | J13: =IF(A13="","",$B$6-1) | K13: =IF(A13="","",C13-1) | L13: =IF(A13="","",IF(OR($B$6<2,$D$6<=Companies!I9),"n.a.",Companies!I9/(($D$6-Companies!I9)/($B$6-1)))) | M13: =IF(A13="","",COUNTIFS(Holdings!$A$6:$A$205,A13,Holdings!$H$6:$H$205,"Passive",Holdings!$K$6:$K$205,1)) | N13: =IF(A13="","",COUNTIFS(Holdings!$A$6:$A$205,A13,Holdings!$H$6:$H$205,"Active",Holdings!$K$6:$K$205,1)) | O13: =IF(A13="","",IF(OR($G$6=0,M13<>$G$6),"n.a.",SUMIFS(Holdings!$D$6:$D$205,Holdings!$A$6:$A$205,A13,Holdings!$H$6:$H$205,"Passive",Holdings!$K$6:$K$205,1)/$I$6)) | P13: =IF(A13="","",IF(OR($H$6=0,N13<>$H$6),"n.a.",SUMIFS(Holdings!$D$6:$D$205,Holdings!$A$6:$A$205,A13,Holdings!$H$6:$H$205,"Active",Holdings!$K$6:$K$205,1)/$J$6)) | Q13: =IF(A13="","",IF(OR($G$6=0,M13<>$G$6),"n.a.",SUMIFS(Holdings!$D$6:$D$205,Holdings!$A$6:$A$205,A13,Holdings!$H$6:$H$205,"Passive",Holdings!$K$6:$K$205,1)/Companies!I9)) | R13: =IF(A13="","",IF(OR($H$6=0,N13<>$H$6),"n.a.",SUMIFS(Holdings!$D$6:$D$205,Holdings!$A$6:$A$205,A13,Holdings!$H$6:$H$205,"Active",Holdings!$K$6:$K$205,1)/Companies!I9)) | S13: =IF(A13="","",IF($G$6+$H$6=0,"No ETF panel",IF(M13+N13=$G$6+$H$6,"Complete selected panel","Missing ETF pairs"))) | T13: {=IF(A13="","",IFNA(INDEX(Network!$L$14:$L$63,MATCH(A13,Network!$A$14:$A$63,0)),"n.a."))} | U13: =IF(A13="","",IF(OR(OR(COUNT(Rules!$B$45:$B$46)<>2,MIN(Rules!$B$45:$B$46)<0,ABS(SUM(Rules!$B$45:$B$46)-1)>0.000001),AND(Rules!$B$45>0,NOT(ISNUMBER(I13))),AND(Rules!$B$46>0,NOT(ISNUMBER(T13)))),"n.a.",IF(Rules!$B$45=0,0,Rules!$B$45*I13)+IF(Rules!$B$46=0,0,Rules!$B$46*T13))) | V13: =IF(A13="","",IF(OR(COUNT(Rules!$B$45:$B$46)<>2,MIN(Rules!$B$45:$B$46)<0,ABS(SUM(Rules!$B$45:$B$46)-1)>0.000001),"Check combined weights",IF(AND(Rules!$B$45>0,NOT(ISNUMBER(I13))),"Scale score unavailable",IF(AND(Rules!$B$46>0,NOT(ISNUMBER(T13))),"Network review/score unavailable","Ready"))))
A14: =IF(Companies!R10=1,Companies!A10,"") | B14: =IF(A14="","",Companies!C10) | C14: =IF(A14="","",1+COUNTIFS(Companies!$R$6:$R$55,1,Companies!$I$6:$I$55,">"&Companies!I10)) | D14: =IF(A14="","",Companies!I10/$D$6) | E14: =IF(A14="","",IF($A$6<>"Ready","n.a.",Companies!K10/$E$6)) | F14: =IF(A14="","",IF(OR($A$6<>"Ready",E14=0),"n.a.",D14/E14)) | G14: =IF(A14="","",IF($B$6<Rules!$B$12,"n.a.",100*(COUNTIFS(Companies!$R$6:$R$55,1,Companies!$I$6:$I$55,"<"&Companies!I10)+0.5*(COUNTIFS(Companies!$R$6:$R$55,1,Companies!$I$6:$I$55,Companies!I10)-1))/($B$6-1))) | H14: =IF(A14="","",IF($A$6<>"Ready","n.a.",100*(COUNTIFS(Companies!$S$6:$S$55,1,Companies!$K$6:$K$55,"<"&Companies!K10)+0.5*(COUNTIFS(Companies!$S$6:$S$55,1,Companies!$K$6:$K$55,Companies!K10)-1))/($C$6-1))) | I14: =IF(A14="","",IF($A$6<>"Ready","n.a.",Rules!$B$13*H14+Rules!$B$14*G14)) | J14: =IF(A14="","",$B$6-1) | K14: =IF(A14="","",C14-1) | L14: =IF(A14="","",IF(OR($B$6<2,$D$6<=Companies!I10),"n.a.",Companies!I10/(($D$6-Companies!I10)/($B$6-1)))) | M14: =IF(A14="","",COUNTIFS(Holdings!$A$6:$A$205,A14,Holdings!$H$6:$H$205,"Passive",Holdings!$K$6:$K$205,1)) | N14: =IF(A14="","",COUNTIFS(Holdings!$A$6:$A$205,A14,Holdings!$H$6:$H$205,"Active",Holdings!$K$6:$K$205,1)) | O14: =IF(A14="","",IF(OR($G$6=0,M14<>$G$6),"n.a.",SUMIFS(Holdings!$D$6:$D$205,Holdings!$A$6:$A$205,A14,Holdings!$H$6:$H$205,"Passive",Holdings!$K$6:$K$205,1)/$I$6)) | P14: =IF(A14="","",IF(OR($H$6=0,N14<>$H$6),"n.a.",SUMIFS(Holdings!$D$6:$D$205,Holdings!$A$6:$A$205,A14,Holdings!$H$6:$H$205,"Active",Holdings!$K$6:$K$205,1)/$J$6)) | Q14: =IF(A14="","",IF(OR($G$6=0,M14<>$G$6),"n.a.",SUMIFS(Holdings!$D$6:$D$205,Holdings!$A$6:$A$205,A14,Holdings!$H$6:$H$205,"Passive",Holdings!$K$6:$K$205,1)/Companies!I10)) | R14: =IF(A14="","",IF(OR($H$6=0,N14<>$H$6),"n.a.",SUMIFS(Holdings!$D$6:$D$205,Holdings!$A$6:$A$205,A14,Holdings!$H$6:$H$205,"Active",Holdings!$K$6:$K$205,1)/Companies!I10)) | S14: =IF(A14="","",IF($G$6+$H$6=0,"No ETF panel",IF(M14+N14=$G$6+$H$6,"Complete selected panel","Missing ETF pairs"))) | T14: {=IF(A14="","",IFNA(INDEX(Network!$L$14:$L$63,MATCH(A14,Network!$A$14:$A$63,0)),"n.a."))} | U14: =IF(A14="","",IF(OR(OR(COUNT(Rules!$B$45:$B$46)<>2,MIN(Rules!$B$45:$B$46)<0,ABS(SUM(Rules!$B$45:$B$46)-1)>0.000001),AND(Rules!$B$45>0,NOT(ISNUMBER(I14))),AND(Rules!$B$46>0,NOT(ISNUMBER(T14)))),"n.a.",IF(Rules!$B$45=0,0,Rules!$B$45*I14)+IF(Rules!$B$46=0,0,Rules!$B$46*T14))) | V14: =IF(A14="","",IF(OR(COUNT(Rules!$B$45:$B$46)<>2,MIN(Rules!$B$45:$B$46)<0,ABS(SUM(Rules!$B$45:$B$46)-1)>0.000001),"Check combined weights",IF(AND(Rules!$B$45>0,NOT(ISNUMBER(I14))),"Scale score unavailable",IF(AND(Rules!$B$46>0,NOT(ISNUMBER(T14))),"Network review/score unavailable","Ready"))))
A15: =IF(Companies!R11=1,Companies!A11,"") | B15: =IF(A15="","",Companies!C11) | C15: =IF(A15="","",1+COUNTIFS(Companies!$R$6:$R$55,1,Companies!$I$6:$I$55,">"&Companies!I11)) | D15: =IF(A15="","",Companies!I11/$D$6) | E15: =IF(A15="","",IF($A$6<>"Ready","n.a.",Companies!K11/$E$6)) | F15: =IF(A15="","",IF(OR($A$6<>"Ready",E15=0),"n.a.",D15/E15)) | G15: =IF(A15="","",IF($B$6<Rules!$B$12,"n.a.",100*(COUNTIFS(Companies!$R$6:$R$55,1,Companies!$I$6:$I$55,"<"&Companies!I11)+0.5*(COUNTIFS(Companies!$R$6:$R$55,1,Companies!$I$6:$I$55,Companies!I11)-1))/($B$6-1))) | H15: =IF(A15="","",IF($A$6<>"Ready","n.a.",100*(COUNTIFS(Companies!$S$6:$S$55,1,Companies!$K$6:$K$55,"<"&Companies!K11)+0.5*(COUNTIFS(Companies!$S$6:$S$55,1,Companies!$K$6:$K$55,Companies!K11)-1))/($C$6-1))) | I15: =IF(A15="","",IF($A$6<>"Ready","n.a.",Rules!$B$13*H15+Rules!$B$14*G15)) | J15: =IF(A15="","",$B$6-1) | K15: =IF(A15="","",C15-1) | L15: =IF(A15="","",IF(OR($B$6<2,$D$6<=Companies!I11),"n.a.",Companies!I11/(($D$6-Companies!I11)/($B$6-1)))) | M15: =IF(A15="","",COUNTIFS(Holdings!$A$6:$A$205,A15,Holdings!$H$6:$H$205,"Passive",Holdings!$K$6:$K$205,1)) | N15: =IF(A15="","",COUNTIFS(Holdings!$A$6:$A$205,A15,Holdings!$H$6:$H$205,"Active",Holdings!$K$6:$K$205,1)) | O15: =IF(A15="","",IF(OR($G$6=0,M15<>$G$6),"n.a.",SUMIFS(Holdings!$D$6:$D$205,Holdings!$A$6:$A$205,A15,Holdings!$H$6:$H$205,"Passive",Holdings!$K$6:$K$205,1)/$I$6)) | P15: =IF(A15="","",IF(OR($H$6=0,N15<>$H$6),"n.a.",SUMIFS(Holdings!$D$6:$D$205,Holdings!$A$6:$A$205,A15,Holdings!$H$6:$H$205,"Active",Holdings!$K$6:$K$205,1)/$J$6)) | Q15: =IF(A15="","",IF(OR($G$6=0,M15<>$G$6),"n.a.",SUMIFS(Holdings!$D$6:$D$205,Holdings!$A$6:$A$205,A15,Holdings!$H$6:$H$205,"Passive",Holdings!$K$6:$K$205,1)/Companies!I11)) | R15: =IF(A15="","",IF(OR($H$6=0,N15<>$H$6),"n.a.",SUMIFS(Holdings!$D$6:$D$205,Holdings!$A$6:$A$205,A15,Holdings!$H$6:$H$205,"Active",Holdings!$K$6:$K$205,1)/Companies!I11)) | S15: =IF(A15="","",IF($G$6+$H$6=0,"No ETF panel",IF(M15+N15=$G$6+$H$6,"Complete selected panel","Missing ETF pairs"))) | T15: {=IF(A15="","",IFNA(INDEX(Network!$L$14:$L$63,MATCH(A15,Network!$A$14:$A$63,0)),"n.a."))} | U15: =IF(A15="","",IF(OR(OR(COUNT(Rules!$B$45:$B$46)<>2,MIN(Rules!$B$45:$B$46)<0,ABS(SUM(Rules!$B$45:$B$46)-1)>0.000001),AND(Rules!$B$45>0,NOT(ISNUMBER(I15))),AND(Rules!$B$46>0,NOT(ISNUMBER(T15)))),"n.a.",IF(Rules!$B$45=0,0,Rules!$B$45*I15)+IF(Rules!$B$46=0,0,Rules!$B$46*T15))) | V15: =IF(A15="","",IF(OR(COUNT(Rules!$B$45:$B$46)<>2,MIN(Rules!$B$45:$B$46)<0,ABS(SUM(Rules!$B$45:$B$46)-1)>0.000001),"Check combined weights",IF(AND(Rules!$B$45>0,NOT(ISNUMBER(I15))),"Scale score unavailable",IF(AND(Rules!$B$46>0,NOT(ISNUMBER(T15))),"Network review/score unavailable","Ready"))))
A16: =IF(Companies!R12=1,Companies!A12,"") | B16: =IF(A16="","",Companies!C12) | C16: =IF(A16="","",1+COUNTIFS(Companies!$R$6:$R$55,1,Companies!$I$6:$I$55,">"&Companies!I12)) | D16: =IF(A16="","",Companies!I12/$D$6) | E16: =IF(A16="","",IF($A$6<>"Ready","n.a.",Companies!K12/$E$6)) | F16: =IF(A16="","",IF(OR($A$6<>"Ready",E16=0),"n.a.",D16/E16)) | G16: =IF(A16="","",IF($B$6<Rules!$B$12,"n.a.",100*(COUNTIFS(Companies!$R$6:$R$55,1,Companies!$I$6:$I$55,"<"&Companies!I12)+0.5*(COUNTIFS(Companies!$R$6:$R$55,1,Companies!$I$6:$I$55,Companies!I12)-1))/($B$6-1))) | H16: =IF(A16="","",IF($A$6<>"Ready","n.a.",100*(COUNTIFS(Companies!$S$6:$S$55,1,Companies!$K$6:$K$55,"<"&Companies!K12)+0.5*(COUNTIFS(Companies!$S$6:$S$55,1,Companies!$K$6:$K$55,Companies!K12)-1))/($C$6-1))) | I16: =IF(A16="","",IF($A$6<>"Ready","n.a.",Rules!$B$13*H16+Rules!$B$14*G16)) | J16: =IF(A16="","",$B$6-1) | K16: =IF(A16="","",C16-1) | L16: =IF(A16="","",IF(OR($B$6<2,$D$6<=Companies!I12),"n.a.",Companies!I12/(($D$6-Companies!I12)/($B$6-1)))) | M16: =IF(A16="","",COUNTIFS(Holdings!$A$6:$A$205,A16,Holdings!$H$6:$H$205,"Passive",Holdings!$K$6:$K$205,1)) | N16: =IF(A16="","",COUNTIFS(Holdings!$A$6:$A$205,A16,Holdings!$H$6:$H$205,"Active",Holdings!$K$6:$K$205,1)) | O16: =IF(A16="","",IF(OR($G$6=0,M16<>$G$6),"n.a.",SUMIFS(Holdings!$D$6:$D$205,Holdings!$A$6:$A$205,A16,Holdings!$H$6:$H$205,"Passive",Holdings!$K$6:$K$205,1)/$I$6)) | P16: =IF(A16="","",IF(OR($H$6=0,N16<>$H$6),"n.a.",SUMIFS(Holdings!$D$6:$D$205,Holdings!$A$6:$A$205,A16,Holdings!$H$6:$H$205,"Active",Holdings!$K$6:$K$205,1)/$J$6)) | Q16: =IF(A16="","",IF(OR($G$6=0,M16<>$G$6),"n.a.",SUMIFS(Holdings!$D$6:$D$205,Holdings!$A$6:$A$205,A16,Holdings!$H$6:$H$205,"Passive",Holdings!$K$6:$K$205,1)/Companies!I12)) | R16: =IF(A16="","",IF(OR($H$6=0,N16<>$H$6),"n.a.",SUMIFS(Holdings!$D$6:$D$205,Holdings!$A$6:$A$205,A16,Holdings!$H$6:$H$205,"Active",Holdings!$K$6:$K$205,1)/Companies!I12)) | S16: =IF(A16="","",IF($G$6+$H$6=0,"No ETF panel",IF(M16+N16=$G$6+$H$6,"Complete selected panel","Missing ETF pairs"))) | T16: {=IF(A16="","",IFNA(INDEX(Network!$L$14:$L$63,MATCH(A16,Network!$A$14:$A$63,0)),"n.a."))} | U16: =IF(A16="","",IF(OR(OR(COUNT(Rules!$B$45:$B$46)<>2,MIN(Rules!$B$45:$B$46)<0,ABS(SUM(Rules!$B$45:$B$46)-1)>0.000001),AND(Rules!$B$45>0,NOT(ISNUMBER(I16))),AND(Rules!$B$46>0,NOT(ISNUMBER(T16)))),"n.a.",IF(Rules!$B$45=0,0,Rules!$B$45*I16)+IF(Rules!$B$46=0,0,Rules!$B$46*T16))) | V16: =IF(A16="","",IF(OR(COUNT(Rules!$B$45:$B$46)<>2,MIN(Rules!$B$45:$B$46)<0,ABS(SUM(Rules!$B$45:$B$46)-1)>0.000001),"Check combined weights",IF(AND(Rules!$B$45>0,NOT(ISNUMBER(I16))),"Scale score unavailable",IF(AND(Rules!$B$46>0,NOT(ISNUMBER(T16))),"Network review/score unavailable","Ready"))))
A17: =IF(Companies!R13=1,Companies!A13,"") | B17: =IF(A17="","",Companies!C13) | C17: =IF(A17="","",1+COUNTIFS(Companies!$R$6:$R$55,1,Companies!$I$6:$I$55,">"&Companies!I13)) | D17: =IF(A17="","",Companies!I13/$D$6) | E17: =IF(A17="","",IF($A$6<>"Ready","n.a.",Companies!K13/$E$6)) | F17: =IF(A17="","",IF(OR($A$6<>"Ready",E17=0),"n.a.",D17/E17)) | G17: =IF(A17="","",IF($B$6<Rules!$B$12,"n.a.",100*(COUNTIFS(Companies!$R$6:$R$55,1,Companies!$I$6:$I$55,"<"&Companies!I13)+0.5*(COUNTIFS(Companies!$R$6:$R$55,1,Companies!$I$6:$I$55,Companies!I13)-1))/($B$6-1))) | H17: =IF(A17="","",IF($A$6<>"Ready","n.a.",100*(COUNTIFS(Companies!$S$6:$S$55,1,Companies!$K$6:$K$55,"<"&Companies!K13)+0.5*(COUNTIFS(Companies!$S$6:$S$55,1,Companies!$K$6:$K$55,Companies!K13)-1))/($C$6-1))) | I17: =IF(A17="","",IF($A$6<>"Ready","n.a.",Rules!$B$13*H17+Rules!$B$14*G17)) | J17: =IF(A17="","",$B$6-1) | K17: =IF(A17="","",C17-1) | L17: =IF(A17="","",IF(OR($B$6<2,$D$6<=Companies!I13),"n.a.",Companies!I13/(($D$6-Companies!I13)/($B$6-1)))) | M17: =IF(A17="","",COUNTIFS(Holdings!$A$6:$A$205,A17,Holdings!$H$6:$H$205,"Passive",Holdings!$K$6:$K$205,1)) | N17: =IF(A17="","",COUNTIFS(Holdings!$A$6:$A$205,A17,Holdings!$H$6:$H$205,"Active",Holdings!$K$6:$K$205,1)) | O17: =IF(A17="","",IF(OR($G$6=0,M17<>$G$6),"n.a.",SUMIFS(Holdings!$D$6:$D$205,Holdings!$A$6:$A$205,A17,Holdings!$H$6:$H$205,"Passive",Holdings!$K$6:$K$205,1)/$I$6)) | P17: =IF(A17="","",IF(OR($H$6=0,N17<>$H$6),"n.a.",SUMIFS(Holdings!$D$6:$D$205,Holdings!$A$6:$A$205,A17,Holdings!$H$6:$H$205,"Active",Holdings!$K$6:$K$205,1)/$J$6)) | Q17: =IF(A17="","",IF(OR($G$6=0,M17<>$G$6),"n.a.",SUMIFS(Holdings!$D$6:$D$205,Holdings!$A$6:$A$205,A17,Holdings!$H$6:$H$205,"Passive",Holdings!$K$6:$K$205,1)/Companies!I13)) | R17: =IF(A17="","",IF(OR($H$6=0,N17<>$H$6),"n.a.",SUMIFS(Holdings!$D$6:$D$205,Holdings!$A$6:$A$205,A17,Holdings!$H$6:$H$205,"Active",Holdings!$K$6:$K$205,1)/Companies!I13)) | S17: =IF(A17="","",IF($G$6+$H$6=0,"No ETF panel",IF(M17+N17=$G$6+$H$6,"Complete selected panel","Missing ETF pairs"))) | T17: {=IF(A17="","",IFNA(INDEX(Network!$L$14:$L$63,MATCH(A17,Network!$A$14:$A$63,0)),"n.a."))} | U17: =IF(A17="","",IF(OR(OR(COUNT(Rules!$B$45:$B$46)<>2,MIN(Rules!$B$45:$B$46)<0,ABS(SUM(Rules!$B$45:$B$46)-1)>0.000001),AND(Rules!$B$45>0,NOT(ISNUMBER(I17))),AND(Rules!$B$46>0,NOT(ISNUMBER(T17)))),"n.a.",IF(Rules!$B$45=0,0,Rules!$B$45*I17)+IF(Rules!$B$46=0,0,Rules!$B$46*T17))) | V17: =IF(A17="","",IF(OR(COUNT(Rules!$B$45:$B$46)<>2,MIN(Rules!$B$45:$B$46)<0,ABS(SUM(Rules!$B$45:$B$46)-1)>0.000001),"Check combined weights",IF(AND(Rules!$B$45>0,NOT(ISNUMBER(I17))),"Scale score unavailable",IF(AND(Rules!$B$46>0,NOT(ISNUMBER(T17))),"Network review/score unavailable","Ready"))))
A18: =IF(Companies!R14=1,Companies!A14,"") | B18: =IF(A18="","",Companies!C14) | C18: =IF(A18="","",1+COUNTIFS(Companies!$R$6:$R$55,1,Companies!$I$6:$I$55,">"&Companies!I14)) | D18: =IF(A18="","",Companies!I14/$D$6) | E18: =IF(A18="","",IF($A$6<>"Ready","n.a.",Companies!K14/$E$6)) | F18: =IF(A18="","",IF(OR($A$6<>"Ready",E18=0),"n.a.",D18/E18)) | G18: =IF(A18="","",IF($B$6<Rules!$B$12,"n.a.",100*(COUNTIFS(Companies!$R$6:$R$55,1,Companies!$I$6:$I$55,"<"&Companies!I14)+0.5*(COUNTIFS(Companies!$R$6:$R$55,1,Companies!$I$6:$I$55,Companies!I14)-1))/($B$6-1))) | H18: =IF(A18="","",IF($A$6<>"Ready","n.a.",100*(COUNTIFS(Companies!$S$6:$S$55,1,Companies!$K$6:$K$55,"<"&Companies!K14)+0.5*(COUNTIFS(Companies!$S$6:$S$55,1,Companies!$K$6:$K$55,Companies!K14)-1))/($C$6-1))) | I18: =IF(A18="","",IF($A$6<>"Ready","n.a.",Rules!$B$13*H18+Rules!$B$14*G18)) | J18: =IF(A18="","",$B$6-1) | K18: =IF(A18="","",C18-1) | L18: =IF(A18="","",IF(OR($B$6<2,$D$6<=Companies!I14),"n.a.",Companies!I14/(($D$6-Companies!I14)/($B$6-1)))) | M18: =IF(A18="","",COUNTIFS(Holdings!$A$6:$A$205,A18,Holdings!$H$6:$H$205,"Passive",Holdings!$K$6:$K$205,1)) | N18: =IF(A18="","",COUNTIFS(Holdings!$A$6:$A$205,A18,Holdings!$H$6:$H$205,"Active",Holdings!$K$6:$K$205,1)) | O18: =IF(A18="","",IF(OR($G$6=0,M18<>$G$6),"n.a.",SUMIFS(Holdings!$D$6:$D$205,Holdings!$A$6:$A$205,A18,Holdings!$H$6:$H$205,"Passive",Holdings!$K$6:$K$205,1)/$I$6)) | P18: =IF(A18="","",IF(OR($H$6=0,N18<>$H$6),"n.a.",SUMIFS(Holdings!$D$6:$D$205,Holdings!$A$6:$A$205,A18,Holdings!$H$6:$H$205,"Active",Holdings!$K$6:$K$205,1)/$J$6)) | Q18: =IF(A18="","",IF(OR($G$6=0,M18<>$G$6),"n.a.",SUMIFS(Holdings!$D$6:$D$205,Holdings!$A$6:$A$205,A18,Holdings!$H$6:$H$205,"Passive",Holdings!$K$6:$K$205,1)/Companies!I14)) | R18: =IF(A18="","",IF(OR($H$6=0,N18<>$H$6),"n.a.",SUMIFS(Holdings!$D$6:$D$205,Holdings!$A$6:$A$205,A18,Holdings!$H$6:$H$205,"Active",Holdings!$K$6:$K$205,1)/Companies!I14)) | S18: =IF(A18="","",IF($G$6+$H$6=0,"No ETF panel",IF(M18+N18=$G$6+$H$6,"Complete selected panel","Missing ETF pairs"))) | T18: {=IF(A18="","",IFNA(INDEX(Network!$L$14:$L$63,MATCH(A18,Network!$A$14:$A$63,0)),"n.a."))} | U18: =IF(A18="","",IF(OR(OR(COUNT(Rules!$B$45:$B$46)<>2,MIN(Rules!$B$45:$B$46)<0,ABS(SUM(Rules!$B$45:$B$46)-1)>0.000001),AND(Rules!$B$45>0,NOT(ISNUMBER(I18))),AND(Rules!$B$46>0,NOT(ISNUMBER(T18)))),"n.a.",IF(Rules!$B$45=0,0,Rules!$B$45*I18)+IF(Rules!$B$46=0,0,Rules!$B$46*T18))) | V18: =IF(A18="","",IF(OR(COUNT(Rules!$B$45:$B$46)<>2,MIN(Rules!$B$45:$B$46)<0,ABS(SUM(Rules!$B$45:$B$46)-1)>0.000001),"Check combined weights",IF(AND(Rules!$B$45>0,NOT(ISNUMBER(I18))),"Scale score unavailable",IF(AND(Rules!$B$46>0,NOT(ISNUMBER(T18))),"Network review/score unavailable","Ready"))))
A19: =IF(Companies!R15=1,Companies!A15,"") | B19: =IF(A19="","",Companies!C15) | C19: =IF(A19="","",1+COUNTIFS(Companies!$R$6:$R$55,1,Companies!$I$6:$I$55,">"&Companies!I15)) | D19: =IF(A19="","",Companies!I15/$D$6) | E19: =IF(A19="","",IF($A$6<>"Ready","n.a.",Companies!K15/$E$6)) | F19: =IF(A19="","",IF(OR($A$6<>"Ready",E19=0),"n.a.",D19/E19)) | G19: =IF(A19="","",IF($B$6<Rules!$B$12,"n.a.",100*(COUNTIFS(Companies!$R$6:$R$55,1,Companies!$I$6:$I$55,"<"&Companies!I15)+0.5*(COUNTIFS(Companies!$R$6:$R$55,1,Companies!$I$6:$I$55,Companies!I15)-1))/($B$6-1))) | H19: =IF(A19="","",IF($A$6<>"Ready","n.a.",100*(COUNTIFS(Companies!$S$6:$S$55,1,Companies!$K$6:$K$55,"<"&Companies!K15)+0.5*(COUNTIFS(Companies!$S$6:$S$55,1,Companies!$K$6:$K$55,Companies!K15)-1))/($C$6-1))) | I19: =IF(A19="","",IF($A$6<>"Ready","n.a.",Rules!$B$13*H19+Rules!$B$14*G19)) | J19: =IF(A19="","",$B$6-1) | K19: =IF(A19="","",C19-1) | L19: =IF(A19="","",IF(OR($B$6<2,$D$6<=Companies!I15),"n.a.",Companies!I15/(($D$6-Companies!I15)/($B$6-1)))) | M19: =IF(A19="","",COUNTIFS(Holdings!$A$6:$A$205,A19,Holdings!$H$6:$H$205,"Passive",Holdings!$K$6:$K$205,1)) | N19: =IF(A19="","",COUNTIFS(Holdings!$A$6:$A$205,A19,Holdings!$H$6:$H$205,"Active",Holdings!$K$6:$K$205,1)) | O19: =IF(A19="","",IF(OR($G$6=0,M19<>$G$6),"n.a.",SUMIFS(Holdings!$D$6:$D$205,Holdings!$A$6:$A$205,A19,Holdings!$H$6:$H$205,"Passive",Holdings!$K$6:$K$205,1)/$I$6)) | P19: =IF(A19="","",IF(OR($H$6=0,N19<>$H$6),"n.a.",SUMIFS(Holdings!$D$6:$D$205,Holdings!$A$6:$A$205,A19,Holdings!$H$6:$H$205,"Active",Holdings!$K$6:$K$205,1)/$J$6)) | Q19: =IF(A19="","",IF(OR($G$6=0,M19<>$G$6),"n.a.",SUMIFS(Holdings!$D$6:$D$205,Holdings!$A$6:$A$205,A19,Holdings!$H$6:$H$205,"Passive",Holdings!$K$6:$K$205,1)/Companies!I15)) | R19: =IF(A19="","",IF(OR($H$6=0,N19<>$H$6),"n.a.",SUMIFS(Holdings!$D$6:$D$205,Holdings!$A$6:$A$205,A19,Holdings!$H$6:$H$205,"Active",Holdings!$K$6:$K$205,1)/Companies!I15)) | S19: =IF(A19="","",IF($G$6+$H$6=0,"No ETF panel",IF(M19+N19=$G$6+$H$6,"Complete selected panel","Missing ETF pairs"))) | T19: {=IF(A19="","",IFNA(INDEX(Network!$L$14:$L$63,MATCH(A19,Network!$A$14:$A$63,0)),"n.a."))} | U19: =IF(A19="","",IF(OR(OR(COUNT(Rules!$B$45:$B$46)<>2,MIN(Rules!$B$45:$B$46)<0,ABS(SUM(Rules!$B$45:$B$46)-1)>0.000001),AND(Rules!$B$45>0,NOT(ISNUMBER(I19))),AND(Rules!$B$46>0,NOT(ISNUMBER(T19)))),"n.a.",IF(Rules!$B$45=0,0,Rules!$B$45*I19)+IF(Rules!$B$46=0,0,Rules!$B$46*T19))) | V19: =IF(A19="","",IF(OR(COUNT(Rules!$B$45:$B$46)<>2,MIN(Rules!$B$45:$B$46)<0,ABS(SUM(Rules!$B$45:$B$46)-1)>0.000001),"Check combined weights",IF(AND(Rules!$B$45>0,NOT(ISNUMBER(I19))),"Scale score unavailable",IF(AND(Rules!$B$46>0,NOT(ISNUMBER(T19))),"Network review/score unavailable","Ready"))))
A20: =IF(Companies!R16=1,Companies!A16,"") | B20: =IF(A20="","",Companies!C16) | C20: =IF(A20="","",1+COUNTIFS(Companies!$R$6:$R$55,1,Companies!$I$6:$I$55,">"&Companies!I16)) | D20: =IF(A20="","",Companies!I16/$D$6) | E20: =IF(A20="","",IF($A$6<>"Ready","n.a.",Companies!K16/$E$6)) | F20: =IF(A20="","",IF(OR($A$6<>"Ready",E20=0),"n.a.",D20/E20)) | G20: =IF(A20="","",IF($B$6<Rules!$B$12,"n.a.",100*(COUNTIFS(Companies!$R$6:$R$55,1,Companies!$I$6:$I$55,"<"&Companies!I16)+0.5*(COUNTIFS(Companies!$R$6:$R$55,1,Companies!$I$6:$I$55,Companies!I16)-1))/($B$6-1))) | H20: =IF(A20="","",IF($A$6<>"Ready","n.a.",100*(COUNTIFS(Companies!$S$6:$S$55,1,Companies!$K$6:$K$55,"<"&Companies!K16)+0.5*(COUNTIFS(Companies!$S$6:$S$55,1,Companies!$K$6:$K$55,Companies!K16)-1))/($C$6-1))) | I20: =IF(A20="","",IF($A$6<>"Ready","n.a.",Rules!$B$13*H20+Rules!$B$14*G20)) | J20: =IF(A20="","",$B$6-1) | K20: =IF(A20="","",C20-1) | L20: =IF(A20="","",IF(OR($B$6<2,$D$6<=Companies!I16),"n.a.",Companies!I16/(($D$6-Companies!I16)/($B$6-1)))) | M20: =IF(A20="","",COUNTIFS(Holdings!$A$6:$A$205,A20,Holdings!$H$6:$H$205,"Passive",Holdings!$K$6:$K$205,1)) | N20: =IF(A20="","",COUNTIFS(Holdings!$A$6:$A$205,A20,Holdings!$H$6:$H$205,"Active",Holdings!$K$6:$K$205,1)) | O20: =IF(A20="","",IF(OR($G$6=0,M20<>$G$6),"n.a.",SUMIFS(Holdings!$D$6:$D$205,Holdings!$A$6:$A$205,A20,Holdings!$H$6:$H$205,"Passive",Holdings!$K$6:$K$205,1)/$I$6)) | P20: =IF(A20="","",IF(OR($H$6=0,N20<>$H$6),"n.a.",SUMIFS(Holdings!$D$6:$D$205,Holdings!$A$6:$A$205,A20,Holdings!$H$6:$H$205,"Active",Holdings!$K$6:$K$205,1)/$J$6)) | Q20: =IF(A20="","",IF(OR($G$6=0,M20<>$G$6),"n.a.",SUMIFS(Holdings!$D$6:$D$205,Holdings!$A$6:$A$205,A20,Holdings!$H$6:$H$205,"Passive",Holdings!$K$6:$K$205,1)/Companies!I16)) | R20: =IF(A20="","",IF(OR($H$6=0,N20<>$H$6),"n.a.",SUMIFS(Holdings!$D$6:$D$205,Holdings!$A$6:$A$205,A20,Holdings!$H$6:$H$205,"Active",Holdings!$K$6:$K$205,1)/Companies!I16)) | S20: =IF(A20="","",IF($G$6+$H$6=0,"No ETF panel",IF(M20+N20=$G$6+$H$6,"Complete selected panel","Missing ETF pairs"))) | T20: {=IF(A20="","",IFNA(INDEX(Network!$L$14:$L$63,MATCH(A20,Network!$A$14:$A$63,0)),"n.a."))} | U20: =IF(A20="","",IF(OR(OR(COUNT(Rules!$B$45:$B$46)<>2,MIN(Rules!$B$45:$B$46)<0,ABS(SUM(Rules!$B$45:$B$46)-1)>0.000001),AND(Rules!$B$45>0,NOT(ISNUMBER(I20))),AND(Rules!$B$46>0,NOT(ISNUMBER(T20)))),"n.a.",IF(Rules!$B$45=0,0,Rules!$B$45*I20)+IF(Rules!$B$46=0,0,Rules!$B$46*T20))) | V20: =IF(A20="","",IF(OR(COUNT(Rules!$B$45:$B$46)<>2,MIN(Rules!$B$45:$B$46)<0,ABS(SUM(Rules!$B$45:$B$46)-1)>0.000001),"Check combined weights",IF(AND(Rules!$B$45>0,NOT(ISNUMBER(I20))),"Scale score unavailable",IF(AND(Rules!$B$46>0,NOT(ISNUMBER(T20))),"Network review/score unavailable","Ready"))))
A21: =IF(Companies!R17=1,Companies!A17,"") | B21: =IF(A21="","",Companies!C17) | C21: =IF(A21="","",1+COUNTIFS(Companies!$R$6:$R$55,1,Companies!$I$6:$I$55,">"&Companies!I17)) | D21: =IF(A21="","",Companies!I17/$D$6) | E21: =IF(A21="","",IF($A$6<>"Ready","n.a.",Companies!K17/$E$6)) | F21: =IF(A21="","",IF(OR($A$6<>"Ready",E21=0),"n.a.",D21/E21)) | G21: =IF(A21="","",IF($B$6<Rules!$B$12,"n.a.",100*(COUNTIFS(Companies!$R$6:$R$55,1,Companies!$I$6:$I$55,"<"&Companies!I17)+0.5*(COUNTIFS(Companies!$R$6:$R$55,1,Companies!$I$6:$I$55,Companies!I17)-1))/($B$6-1))) | H21: =IF(A21="","",IF($A$6<>"Ready","n.a.",100*(COUNTIFS(Companies!$S$6:$S$55,1,Companies!$K$6:$K$55,"<"&Companies!K17)+0.5*(COUNTIFS(Companies!$S$6:$S$55,1,Companies!$K$6:$K$55,Companies!K17)-1))/($C$6-1))) | I21: =IF(A21="","",IF($A$6<>"Ready","n.a.",Rules!$B$13*H21+Rules!$B$14*G21)) | J21: =IF(A21="","",$B$6-1) | K21: =IF(A21="","",C21-1) | L21: =IF(A21="","",IF(OR($B$6<2,$D$6<=Companies!I17),"n.a.",Companies!I17/(($D$6-Companies!I17)/($B$6-1)))) | M21: =IF(A21="","",COUNTIFS(Holdings!$A$6:$A$205,A21,Holdings!$H$6:$H$205,"Passive",Holdings!$K$6:$K$205,1)) | N21: =IF(A21="","",COUNTIFS(Holdings!$A$6:$A$205,A21,Holdings!$H$6:$H$205,"Active",Holdings!$K$6:$K$205,1)) | O21: =IF(A21="","",IF(OR($G$6=0,M21<>$G$6),"n.a.",SUMIFS(Holdings!$D$6:$D$205,Holdings!$A$6:$A$205,A21,Holdings!$H$6:$H$205,"Passive",Holdings!$K$6:$K$205,1)/$I$6)) | P21: =IF(A21="","",IF(OR($H$6=0,N21<>$H$6),"n.a.",SUMIFS(Holdings!$D$6:$D$205,Holdings!$A$6:$A$205,A21,Holdings!$H$6:$H$205,"Active",Holdings!$K$6:$K$205,1)/$J$6)) | Q21: =IF(A21="","",IF(OR($G$6=0,M21<>$G$6),"n.a.",SUMIFS(Holdings!$D$6:$D$205,Holdings!$A$6:$A$205,A21,Holdings!$H$6:$H$205,"Passive",Holdings!$K$6:$K$205,1)/Companies!I17)) | R21: =IF(A21="","",IF(OR($H$6=0,N21<>$H$6),"n.a.",SUMIFS(Holdings!$D$6:$D$205,Holdings!$A$6:$A$205,A21,Holdings!$H$6:$H$205,"Active",Holdings!$K$6:$K$205,1)/Companies!I17)) | S21: =IF(A21="","",IF($G$6+$H$6=0,"No ETF panel",IF(M21+N21=$G$6+$H$6,"Complete selected panel","Missing ETF pairs"))) | T21: {=IF(A21="","",IFNA(INDEX(Network!$L$14:$L$63,MATCH(A21,Network!$A$14:$A$63,0)),"n.a."))} | U21: =IF(A21="","",IF(OR(OR(COUNT(Rules!$B$45:$B$46)<>2,MIN(Rules!$B$45:$B$46)<0,ABS(SUM(Rules!$B$45:$B$46)-1)>0.000001),AND(Rules!$B$45>0,NOT(ISNUMBER(I21))),AND(Rules!$B$46>0,NOT(ISNUMBER(T21)))),"n.a.",IF(Rules!$B$45=0,0,Rules!$B$45*I21)+IF(Rules!$B$46=0,0,Rules!$B$46*T21))) | V21: =IF(A21="","",IF(OR(COUNT(Rules!$B$45:$B$46)<>2,MIN(Rules!$B$45:$B$46)<0,ABS(SUM(Rules!$B$45:$B$46)-1)>0.000001),"Check combined weights",IF(AND(Rules!$B$45>0,NOT(ISNUMBER(I21))),"Scale score unavailable",IF(AND(Rules!$B$46>0,NOT(ISNUMBER(T21))),"Network review/score unavailable","Ready"))))
... A59: =IF(Companies!R55=1,Companies!A55,"") | B59: =IF(A59="","",Companies!C55) | C59: =IF(A59="","",1+COUNTIFS(Companies!$R$6:$R$55,1,Companies!$I$6:$I$55,">"&Companies!I55)) | D59: =IF(A59="","",Companies!I55/$D$6) | E59: =IF(A59="","",IF($A$6<>"Ready","n.a.",Companies!K55/$E$6)) | F59: =IF(A59="","",IF(OR($A$6<>"Ready",E59=0),"n.a.",D59/E59)) | G59: =IF(A59="","",IF($B$6<Rules!$B$12,"n.a.",100*(COUNTIFS(Companies!$R$6:$R$55,1,Companies!$I$6:$I$55,"<"&Companies!I55)+0.5*(COUNTIFS(Companies!$R$6:$R$55,1,Companies!$I$6:$I$55,Companies!I55)-1))/($B$6-1))) | H59: =IF(A59="","",IF($A$6<>"Ready","n.a.",100*(COUNTIFS(Companies!$S$6:$S$55,1,Companies!$K$6:$K$55,"<"&Companies!K55)+0.5*(COUNTIFS(Companies!$S$6:$S$55,1,Companies!$K$6:$K$55,Companies!K55)-1))/($C$6-1))) | I59: =IF(A59="","",IF($A$6<>"Ready","n.a.",Rules!$B$13*H59+Rules!$B$14*G59)) | J59: =IF(A59="","",$B$6-1) | K59: =IF(A59="","",C59-1) | L59: =IF(A59="","",IF(OR($B$6<2,$D$6<=Companies!I55),"n.a.",Companies!I55/(($D$6-Companies!I55)/($B$6-1)))) | M59: =IF(A59="","",COUNTIFS(Holdings!$A$6:$A$205,A59,Holdings!$H$6:$H$205,"Passive",Holdings!$K$6:$K$205,1)) | N59: =IF(A59="","",COUNTIFS(Holdings!$A$6:$A$205,A59,Holdings!$H$6:$H$205,"Active",Holdings!$K$6:$K$205,1)) | O59: =IF(A59="","",IF(OR($G$6=0,M59<>$G$6),"n.a.",SUMIFS(Holdings!$D$6:$D$205,Holdings!$A$6:$A$205,A59,Holdings!$H$6:$H$205,"Passive",Holdings!$K$6:$K$205,1)/$I$6)) | P59: =IF(A59="","",IF(OR($H$6=0,N59<>$H$6),"n.a.",SUMIFS(Holdings!$D$6:$D$205,Holdings!$A$6:$A$205,A59,Holdings!$H$6:$H$205,"Active",Holdings!$K$6:$K$205,1)/$J$6)) | Q59: =IF(A59="","",IF(OR($G$6=0,M59<>$G$6),"n.a.",SUMIFS(Holdings!$D$6:$D$205,Holdings!$A$6:$A$205,A59,Holdings!$H$6:$H$205,"Passive",Holdings!$K$6:$K$205,1)/Companies!I55)) | R59: =IF(A59="","",IF(OR($H$6=0,N59<>$H$6),"n.a.",SUMIFS(Holdings!$D$6:$D$205,Holdings!$A$6:$A$205,A59,Holdings!$H$6:$H$205,"Active",Holdings!$K$6:$K$205,1)/Companies!I55)) | S59: =IF(A59="","",IF($G$6+$H$6=0,"No ETF panel",IF(M59+N59=$G$6+$H$6,"Complete selected panel","Missing ETF pairs"))) | T59: {=IF(A59="","",IFNA(INDEX(Network!$L$14:$L$63,MATCH(A59,Network!$A$14:$A$63,0)),"n.a."))} | U59: =IF(A59="","",IF(OR(OR(COUNT(Rules!$B$45:$B$46)<>2,MIN(Rules!$B$45:$B$46)<0,ABS(SUM(Rules!$B$45:$B$46)-1)>0.000001),AND(Rules!$B$45>0,NOT(ISNUMBER(I59))),AND(Rules!$B$46>0,NOT(ISNUMBER(T59)))),"n.a.",IF(Rules!$B$45=0,0,Rules!$B$45*I59)+IF(Rules!$B$46=0,0,Rules!$B$46*T59))) | V59: =IF(A59="","",IF(OR(COUNT(Rules!$B$45:$B$46)<>2,MIN(Rules!$B$45:$B$46)<0,ABS(SUM(Rules!$B$45:$B$46)-1)>0.000001),"Check combined weights",IF(AND(Rules!$B$45>0,NOT(ISNUMBER(I59))),"Scale score unavailable",IF(AND(Rules!$B$46>0,NOT(ISNUMBER(T59))),"Network review/score unavailable","Ready"))))

Sheet Network
A2: Client and partner network strength
A3: Draft relative network score. Complete the dated review for each issuer; only verified public-company ties >= USD10bn qualify.
A4: Research snapshot | B4: =Rules!B6 -> 46298 | F4: Network component | G4: Weight
A5: Cap-eligible issuers | B5: =COUNTIF(Companies!$R$6:$R$55,1) -> 0 | F5: Breadth | G5: =Rules!B43 -> 0.5
A6: Scorable reviews | B6: =COUNTIF($P$14:$P$63,1) -> 0 | F6: Median cap | G6: =Rules!B44 -> 0.5
A7: Review coverage | B7: =IF(B5=0,"n.a.",B6/B5) -> n.a.
A8: Network status | B8: =IF(Rules!B15<>"Yes","Confirm issuer universe",IF(OR(COUNT(G5:G6)<>2,MIN(G5:G6)<0,ABS(SUM(G5:G6)-1)>0.000001),"Check network weights",IF(B10>0,"Assign relationship issuer IDs",IF(B6<B9,"Too few reviewed companies","Ready")))) -> Confirm issuer universe | F8: Competitive blend | G8: Weight
A9: Minimum comparison count | B9: =Rules!B12 -> 3 | F9: Scale | G9: =Rules!B45 -> 0.5
A10: Orphan included records | B10: =COUNTIFS(Relationships!$L$6:$L$205,"Yes",Relationships!$M$6:$M$205,0,Relationships!$E$6:$E$205,"Active")+COUNTIFS(Relationships!$L$6:$L$205,"Yes",Relationships!$M$6:$M$205,0,Relationships!$E$6:$E$205,"Unclear")+COUNTIFS(Relationships!$L$6:$L$205,"Yes",Relationships!$M$6:$M$205,0,Relationships!$E$6:$E$205,"") -> 0 | F10: Network | G10: =Rules!B46 -> 0.5
F11: Weights are draft assumptions.
F12: Higher scores mean broader/larger disclosed networks.
A13: Issuer ID | B13: Company | C13: Review complete? | D13: Review date | E13: Review source / scope log | F13: Qualifying counterparties | G13: Clients | H13: Partners | I13: Median counterparty cap USD bn | J13: Breadth score /100 | K13: Size score /100 | L13: Network score /100 | M13: Network rank | N13: Unresolved included records | O13: Row status | P13: Scorable | Q13: Subject cap eligible | R13: Issuer ID count | S13: Scorable median cap
B14: {=IF(A14="","",IF(COUNTIF(Companies!$A$6:$A$55,A14)<>1,"n.a.",INDEX(Companies!$C$6:$C$55,MATCH(A14,Companies!$A$6:$A$55,0))))} | F14: =IF(A14="","",COUNTIFS(Relationships!$A$6:$A$205,A14,Relationships!$U$6:$U$205,1)) | G14: =IF(A14="","",COUNTIFS(Relationships!$A$6:$A$205,A14,Relationships!$U$6:$U$205,1,Relationships!$C$6:$C$205,"Client")+COUNTIFS(Relationships!$A$6:$A$205,A14,Relationships!$U$6:$U$205,1,Relationships!$C$6:$C$205,"Client and partner")) | H14: =IF(A14="","",COUNTIFS(Relationships!$A$6:$A$205,A14,Relationships!$U$6:$U$205,1,Relationships!$C$6:$C$205,"Partner")+COUNTIFS(Relationships!$A$6:$A$205,A14,Relationships!$U$6:$U$205,1,Relationships!$C$6:$C$205,"Client and partner")) | I14: =IFERROR(__xludf.DUMMYFUNCTION("IF(A14="""","""",IF(F14=0,""n.a."",MEDIAN(FILTER(Relationships!$Q$6:$Q$205,Relationships!$A$6:$A$205=A14,Relationships!$U$6:$U$205=1))))"),"") | J14: =IF(A14="","",IF(OR(P14<>1,$B$8<>"Ready"),"n.a.",IF(F14=0,0,100*(COUNTIFS($P$14:$P$63,1,$F$14:$F$63,"<"&F14)+0.5*(COUNTIFS($P$14:$P$63,1,$F$14:$F$63,F14)-1))/($B$6-1)))) | K14: =IF(A14="","",IF(OR(P14<>1,$B$8<>"Ready"),"n.a.",IF(F14=0,0,100*(COUNTIFS($P$14:$P$63,1,$S$14:$S$63,"<"&I14)+0.5*(COUNTIFS($P$14:$P$63,1,$S$14:$S$63,I14)-1))/($B$6-1)))) | L14: =IF(A14="","",IF(OR(P14<>1,$B$8<>"Ready"),"n.a.",$G$5*J14+$G$6*K14)) | M14: =IF(A14="","",IF(NOT(ISNUMBER(L14)),"n.a.",1+COUNTIFS($P$14:$P$63,1,$L$14:$L$63,">"&L14))) | N14: =IF(A14="","",COUNTIFS(Relationships!$A$6:$A$205,A14,Relationships!$V$6:$V$205,1)) | O14: =IF(A14="","",IF(Q14<>1,"Outside cap universe",IF(R14<>1,"Duplicate network issuer",IF(C14<>"Yes","Review incomplete",IF(OR(NOT(ISNUMBER(D14)),D14>Rules!$B$6,Rules!$B$6-D14>Rules!$B$42,E14=""),"Check review date/log",IF(N14>0,"Resolve included records",IF($B$8<>"Ready",$B$8,IF(F14=0,"Reviewed: no qualifying ties","Ranked")))))))) | P14: =IF(A14="",0,IF(AND(Q14=1,R14=1,C14="Yes",ISNUMBER(D14),D14<=Rules!$B$6,Rules!$B$6-D14<=Rules!$B$42,E14<>"",N14=0),1,0)) -> 0 | Q14: {=IF(A14="",0,IF(COUNTIF(Companies!$A$6:$A$55,A14)<>1,0,IF(AND(INDEX(Companies!$R$6:$R$55,MATCH(A14,Companies!$A$6:$A$55,0))=1,INDEX(Companies!$I$6:$I$55,MATCH(A14,Companies!$A$6:$A$55,0))>=MAX(10,Rules!$B$22)),1,0)))} -> 0 | R14: =IF(A14="","",COUNTIF($A$14:$A$63,A14)) | S14: =IF(P14<>1,"",IF(F14=0,0,I14))
B15: {=IF(A15="","",IF(COUNTIF(Companies!$A$6:$A$55,A15)<>1,"n.a.",INDEX(Companies!$C$6:$C$55,MATCH(A15,Companies!$A$6:$A$55,0))))} | F15: =IF(A15="","",COUNTIFS(Relationships!$A$6:$A$205,A15,Relationships!$U$6:$U$205,1)) | G15: =IF(A15="","",COUNTIFS(Relationships!$A$6:$A$205,A15,Relationships!$U$6:$U$205,1,Relationships!$C$6:$C$205,"Client")+COUNTIFS(Relationships!$A$6:$A$205,A15,Relationships!$U$6:$U$205,1,Relationships!$C$6:$C$205,"Client and partner")) | H15: =IF(A15="","",COUNTIFS(Relationships!$A$6:$A$205,A15,Relationships!$U$6:$U$205,1,Relationships!$C$6:$C$205,"Partner")+COUNTIFS(Relationships!$A$6:$A$205,A15,Relationships!$U$6:$U$205,1,Relationships!$C$6:$C$205,"Client and partner")) | I15: =IFERROR(__xludf.DUMMYFUNCTION("IF(A15="""","""",IF(F15=0,""n.a."",MEDIAN(FILTER(Relationships!$Q$6:$Q$205,Relationships!$A$6:$A$205=A15,Relationships!$U$6:$U$205=1))))"),"") | J15: =IF(A15="","",IF(OR(P15<>1,$B$8<>"Ready"),"n.a.",IF(F15=0,0,100*(COUNTIFS($P$14:$P$63,1,$F$14:$F$63,"<"&F15)+0.5*(COUNTIFS($P$14:$P$63,1,$F$14:$F$63,F15)-1))/($B$6-1)))) | K15: =IF(A15="","",IF(OR(P15<>1,$B$8<>"Ready"),"n.a.",IF(F15=0,0,100*(COUNTIFS($P$14:$P$63,1,$S$14:$S$63,"<"&I15)+0.5*(COUNTIFS($P$14:$P$63,1,$S$14:$S$63,I15)-1))/($B$6-1)))) | L15: =IF(A15="","",IF(OR(P15<>1,$B$8<>"Ready"),"n.a.",$G$5*J15+$G$6*K15)) | M15: =IF(A15="","",IF(NOT(ISNUMBER(L15)),"n.a.",1+COUNTIFS($P$14:$P$63,1,$L$14:$L$63,">"&L15))) | N15: =IF(A15="","",COUNTIFS(Relationships!$A$6:$A$205,A15,Relationships!$V$6:$V$205,1)) | O15: =IF(A15="","",IF(Q15<>1,"Outside cap universe",IF(R15<>1,"Duplicate network issuer",IF(C15<>"Yes","Review incomplete",IF(OR(NOT(ISNUMBER(D15)),D15>Rules!$B$6,Rules!$B$6-D15>Rules!$B$42,E15=""),"Check review date/log",IF(N15>0,"Resolve included records",IF($B$8<>"Ready",$B$8,IF(F15=0,"Reviewed: no qualifying ties","Ranked")))))))) | P15: =IF(A15="",0,IF(AND(Q15=1,R15=1,C15="Yes",ISNUMBER(D15),D15<=Rules!$B$6,Rules!$B$6-D15<=Rules!$B$42,E15<>"",N15=0),1,0)) -> 0 | Q15: {=IF(A15="",0,IF(COUNTIF(Companies!$A$6:$A$55,A15)<>1,0,IF(AND(INDEX(Companies!$R$6:$R$55,MATCH(A15,Companies!$A$6:$A$55,0))=1,INDEX(Companies!$I$6:$I$55,MATCH(A15,Companies!$A$6:$A$55,0))>=MAX(10,Rules!$B$22)),1,0)))} -> 0 | R15: =IF(A15="","",COUNTIF($A$14:$A$63,A15)) | S15: =IF(P15<>1,"",IF(F15=0,0,I15))
B16: {=IF(A16="","",IF(COUNTIF(Companies!$A$6:$A$55,A16)<>1,"n.a.",INDEX(Companies!$C$6:$C$55,MATCH(A16,Companies!$A$6:$A$55,0))))} | F16: =IF(A16="","",COUNTIFS(Relationships!$A$6:$A$205,A16,Relationships!$U$6:$U$205,1)) | G16: =IF(A16="","",COUNTIFS(Relationships!$A$6:$A$205,A16,Relationships!$U$6:$U$205,1,Relationships!$C$6:$C$205,"Client")+COUNTIFS(Relationships!$A$6:$A$205,A16,Relationships!$U$6:$U$205,1,Relationships!$C$6:$C$205,"Client and partner")) | H16: =IF(A16="","",COUNTIFS(Relationships!$A$6:$A$205,A16,Relationships!$U$6:$U$205,1,Relationships!$C$6:$C$205,"Partner")+COUNTIFS(Relationships!$A$6:$A$205,A16,Relationships!$U$6:$U$205,1,Relationships!$C$6:$C$205,"Client and partner")) | I16: =IFERROR(__xludf.DUMMYFUNCTION("IF(A16="""","""",IF(F16=0,""n.a."",MEDIAN(FILTER(Relationships!$Q$6:$Q$205,Relationships!$A$6:$A$205=A16,Relationships!$U$6:$U$205=1))))"),"") | J16: =IF(A16="","",IF(OR(P16<>1,$B$8<>"Ready"),"n.a.",IF(F16=0,0,100*(COUNTIFS($P$14:$P$63,1,$F$14:$F$63,"<"&F16)+0.5*(COUNTIFS($P$14:$P$63,1,$F$14:$F$63,F16)-1))/($B$6-1)))) | K16: =IF(A16="","",IF(OR(P16<>1,$B$8<>"Ready"),"n.a.",IF(F16=0,0,100*(COUNTIFS($P$14:$P$63,1,$S$14:$S$63,"<"&I16)+0.5*(COUNTIFS($P$14:$P$63,1,$S$14:$S$63,I16)-1))/($B$6-1)))) | L16: =IF(A16="","",IF(OR(P16<>1,$B$8<>"Ready"),"n.a.",$G$5*J16+$G$6*K16)) | M16: =IF(A16="","",IF(NOT(ISNUMBER(L16)),"n.a.",1+COUNTIFS($P$14:$P$63,1,$L$14:$L$63,">"&L16))) | N16: =IF(A16="","",COUNTIFS(Relationships!$A$6:$A$205,A16,Relationships!$V$6:$V$205,1)) | O16: =IF(A16="","",IF(Q16<>1,"Outside cap universe",IF(R16<>1,"Duplicate network issuer",IF(C16<>"Yes","Review incomplete",IF(OR(NOT(ISNUMBER(D16)),D16>Rules!$B$6,Rules!$B$6-D16>Rules!$B$42,E16=""),"Check review date/log",IF(N16>0,"Resolve included records",IF($B$8<>"Ready",$B$8,IF(F16=0,"Reviewed: no qualifying ties","Ranked")))))))) | P16: =IF(A16="",0,IF(AND(Q16=1,R16=1,C16="Yes",ISNUMBER(D16),D16<=Rules!$B$6,Rules!$B$6-D16<=Rules!$B$42,E16<>"",N16=0),1,0)) -> 0 | Q16: {=IF(A16="",0,IF(COUNTIF(Companies!$A$6:$A$55,A16)<>1,0,IF(AND(INDEX(Companies!$R$6:$R$55,MATCH(A16,Companies!$A$6:$A$55,0))=1,INDEX(Companies!$I$6:$I$55,MATCH(A16,Companies!$A$6:$A$55,0))>=MAX(10,Rules!$B$22)),1,0)))} -> 0 | R16: =IF(A16="","",COUNTIF($A$14:$A$63,A16)) | S16: =IF(P16<>1,"",IF(F16=0,0,I16))
B17: {=IF(A17="","",IF(COUNTIF(Companies!$A$6:$A$55,A17)<>1,"n.a.",INDEX(Companies!$C$6:$C$55,MATCH(A17,Companies!$A$6:$A$55,0))))} | F17: =IF(A17="","",COUNTIFS(Relationships!$A$6:$A$205,A17,Relationships!$U$6:$U$205,1)) | G17: =IF(A17="","",COUNTIFS(Relationships!$A$6:$A$205,A17,Relationships!$U$6:$U$205,1,Relationships!$C$6:$C$205,"Client")+COUNTIFS(Relationships!$A$6:$A$205,A17,Relationships!$U$6:$U$205,1,Relationships!$C$6:$C$205,"Client and partner")) | H17: =IF(A17="","",COUNTIFS(Relationships!$A$6:$A$205,A17,Relationships!$U$6:$U$205,1,Relationships!$C$6:$C$205,"Partner")+COUNTIFS(Relationships!$A$6:$A$205,A17,Relationships!$U$6:$U$205,1,Relationships!$C$6:$C$205,"Client and partner")) | I17: =IFERROR(__xludf.DUMMYFUNCTION("IF(A17="""","""",IF(F17=0,""n.a."",MEDIAN(FILTER(Relationships!$Q$6:$Q$205,Relationships!$A$6:$A$205=A17,Relationships!$U$6:$U$205=1))))"),"") | J17: =IF(A17="","",IF(OR(P17<>1,$B$8<>"Ready"),"n.a.",IF(F17=0,0,100*(COUNTIFS($P$14:$P$63,1,$F$14:$F$63,"<"&F17)+0.5*(COUNTIFS($P$14:$P$63,1,$F$14:$F$63,F17)-1))/($B$6-1)))) | K17: =IF(A17="","",IF(OR(P17<>1,$B$8<>"Ready"),"n.a.",IF(F17=0,0,100*(COUNTIFS($P$14:$P$63,1,$S$14:$S$63,"<"&I17)+0.5*(COUNTIFS($P$14:$P$63,1,$S$14:$S$63,I17)-1))/($B$6-1)))) | L17: =IF(A17="","",IF(OR(P17<>1,$B$8<>"Ready"),"n.a.",$G$5*J17+$G$6*K17)) | M17: =IF(A17="","",IF(NOT(ISNUMBER(L17)),"n.a.",1+COUNTIFS($P$14:$P$63,1,$L$14:$L$63,">"&L17))) | N17: =IF(A17="","",COUNTIFS(Relationships!$A$6:$A$205,A17,Relationships!$V$6:$V$205,1)) | O17: =IF(A17="","",IF(Q17<>1,"Outside cap universe",IF(R17<>1,"Duplicate network issuer",IF(C17<>"Yes","Review incomplete",IF(OR(NOT(ISNUMBER(D17)),D17>Rules!$B$6,Rules!$B$6-D17>Rules!$B$42,E17=""),"Check review date/log",IF(N17>0,"Resolve included records",IF($B$8<>"Ready",$B$8,IF(F17=0,"Reviewed: no qualifying ties","Ranked")))))))) | P17: =IF(A17="",0,IF(AND(Q17=1,R17=1,C17="Yes",ISNUMBER(D17),D17<=Rules!$B$6,Rules!$B$6-D17<=Rules!$B$42,E17<>"",N17=0),1,0)) -> 0 | Q17: {=IF(A17="",0,IF(COUNTIF(Companies!$A$6:$A$55,A17)<>1,0,IF(AND(INDEX(Companies!$R$6:$R$55,MATCH(A17,Companies!$A$6:$A$55,0))=1,INDEX(Companies!$I$6:$I$55,MATCH(A17,Companies!$A$6:$A$55,0))>=MAX(10,Rules!$B$22)),1,0)))} -> 0 | R17: =IF(A17="","",COUNTIF($A$14:$A$63,A17)) | S17: =IF(P17<>1,"",IF(F17=0,0,I17))
B18: {=IF(A18="","",IF(COUNTIF(Companies!$A$6:$A$55,A18)<>1,"n.a.",INDEX(Companies!$C$6:$C$55,MATCH(A18,Companies!$A$6:$A$55,0))))} | F18: =IF(A18="","",COUNTIFS(Relationships!$A$6:$A$205,A18,Relationships!$U$6:$U$205,1)) | G18: =IF(A18="","",COUNTIFS(Relationships!$A$6:$A$205,A18,Relationships!$U$6:$U$205,1,Relationships!$C$6:$C$205,"Client")+COUNTIFS(Relationships!$A$6:$A$205,A18,Relationships!$U$6:$U$205,1,Relationships!$C$6:$C$205,"Client and partner")) | H18: =IF(A18="","",COUNTIFS(Relationships!$A$6:$A$205,A18,Relationships!$U$6:$U$205,1,Relationships!$C$6:$C$205,"Partner")+COUNTIFS(Relationships!$A$6:$A$205,A18,Relationships!$U$6:$U$205,1,Relationships!$C$6:$C$205,"Client and partner")) | I18: =IFERROR(__xludf.DUMMYFUNCTION("IF(A18="""","""",IF(F18=0,""n.a."",MEDIAN(FILTER(Relationships!$Q$6:$Q$205,Relationships!$A$6:$A$205=A18,Relationships!$U$6:$U$205=1))))"),"") | J18: =IF(A18="","",IF(OR(P18<>1,$B$8<>"Ready"),"n.a.",IF(F18=0,0,100*(COUNTIFS($P$14:$P$63,1,$F$14:$F$63,"<"&F18)+0.5*(COUNTIFS($P$14:$P$63,1,$F$14:$F$63,F18)-1))/($B$6-1)))) | K18: =IF(A18="","",IF(OR(P18<>1,$B$8<>"Ready"),"n.a.",IF(F18=0,0,100*(COUNTIFS($P$14:$P$63,1,$S$14:$S$63,"<"&I18)+0.5*(COUNTIFS($P$14:$P$63,1,$S$14:$S$63,I18)-1))/($B$6-1)))) | L18: =IF(A18="","",IF(OR(P18<>1,$B$8<>"Ready"),"n.a.",$G$5*J18+$G$6*K18)) | M18: =IF(A18="","",IF(NOT(ISNUMBER(L18)),"n.a.",1+COUNTIFS($P$14:$P$63,1,$L$14:$L$63,">"&L18))) | N18: =IF(A18="","",COUNTIFS(Relationships!$A$6:$A$205,A18,Relationships!$V$6:$V$205,1)) | O18: =IF(A18="","",IF(Q18<>1,"Outside cap universe",IF(R18<>1,"Duplicate network issuer",IF(C18<>"Yes","Review incomplete",IF(OR(NOT(ISNUMBER(D18)),D18>Rules!$B$6,Rules!$B$6-D18>Rules!$B$42,E18=""),"Check review date/log",IF(N18>0,"Resolve included records",IF($B$8<>"Ready",$B$8,IF(F18=0,"Reviewed: no qualifying ties","Ranked")))))))) | P18: =IF(A18="",0,IF(AND(Q18=1,R18=1,C18="Yes",ISNUMBER(D18),D18<=Rules!$B$6,Rules!$B$6-D18<=Rules!$B$42,E18<>"",N18=0),1,0)) -> 0 | Q18: {=IF(A18="",0,IF(COUNTIF(Companies!$A$6:$A$55,A18)<>1,0,IF(AND(INDEX(Companies!$R$6:$R$55,MATCH(A18,Companies!$A$6:$A$55,0))=1,INDEX(Companies!$I$6:$I$55,MATCH(A18,Companies!$A$6:$A$55,0))>=MAX(10,Rules!$B$22)),1,0)))} -> 0 | R18: =IF(A18="","",COUNTIF($A$14:$A$63,A18)) | S18: =IF(P18<>1,"",IF(F18=0,0,I18))
B19: {=IF(A19="","",IF(COUNTIF(Companies!$A$6:$A$55,A19)<>1,"n.a.",INDEX(Companies!$C$6:$C$55,MATCH(A19,Companies!$A$6:$A$55,0))))} | F19: =IF(A19="","",COUNTIFS(Relationships!$A$6:$A$205,A19,Relationships!$U$6:$U$205,1)) | G19: =IF(A19="","",COUNTIFS(Relationships!$A$6:$A$205,A19,Relationships!$U$6:$U$205,1,Relationships!$C$6:$C$205,"Client")+COUNTIFS(Relationships!$A$6:$A$205,A19,Relationships!$U$6:$U$205,1,Relationships!$C$6:$C$205,"Client and partner")) | H19: =IF(A19="","",COUNTIFS(Relationships!$A$6:$A$205,A19,Relationships!$U$6:$U$205,1,Relationships!$C$6:$C$205,"Partner")+COUNTIFS(Relationships!$A$6:$A$205,A19,Relationships!$U$6:$U$205,1,Relationships!$C$6:$C$205,"Client and partner")) | I19: =IFERROR(__xludf.DUMMYFUNCTION("IF(A19="""","""",IF(F19=0,""n.a."",MEDIAN(FILTER(Relationships!$Q$6:$Q$205,Relationships!$A$6:$A$205=A19,Relationships!$U$6:$U$205=1))))"),"") | J19: =IF(A19="","",IF(OR(P19<>1,$B$8<>"Ready"),"n.a.",IF(F19=0,0,100*(COUNTIFS($P$14:$P$63,1,$F$14:$F$63,"<"&F19)+0.5*(COUNTIFS($P$14:$P$63,1,$F$14:$F$63,F19)-1))/($B$6-1)))) | K19: =IF(A19="","",IF(OR(P19<>1,$B$8<>"Ready"),"n.a.",IF(F19=0,0,100*(COUNTIFS($P$14:$P$63,1,$S$14:$S$63,"<"&I19)+0.5*(COUNTIFS($P$14:$P$63,1,$S$14:$S$63,I19)-1))/($B$6-1)))) | L19: =IF(A19="","",IF(OR(P19<>1,$B$8<>"Ready"),"n.a.",$G$5*J19+$G$6*K19)) | M19: =IF(A19="","",IF(NOT(ISNUMBER(L19)),"n.a.",1+COUNTIFS($P$14:$P$63,1,$L$14:$L$63,">"&L19))) | N19: =IF(A19="","",COUNTIFS(Relationships!$A$6:$A$205,A19,Relationships!$V$6:$V$205,1)) | O19: =IF(A19="","",IF(Q19<>1,"Outside cap universe",IF(R19<>1,"Duplicate network issuer",IF(C19<>"Yes","Review incomplete",IF(OR(NOT(ISNUMBER(D19)),D19>Rules!$B$6,Rules!$B$6-D19>Rules!$B$42,E19=""),"Check review date/log",IF(N19>0,"Resolve included records",IF($B$8<>"Ready",$B$8,IF(F19=0,"Reviewed: no qualifying ties","Ranked")))))))) | P19: =IF(A19="",0,IF(AND(Q19=1,R19=1,C19="Yes",ISNUMBER(D19),D19<=Rules!$B$6,Rules!$B$6-D19<=Rules!$B$42,E19<>"",N19=0),1,0)) -> 0 | Q19: {=IF(A19="",0,IF(COUNTIF(Companies!$A$6:$A$55,A19)<>1,0,IF(AND(INDEX(Companies!$R$6:$R$55,MATCH(A19,Companies!$A$6:$A$55,0))=1,INDEX(Companies!$I$6:$I$55,MATCH(A19,Companies!$A$6:$A$55,0))>=MAX(10,Rules!$B$22)),1,0)))} -> 0 | R19: =IF(A19="","",COUNTIF($A$14:$A$63,A19)) | S19: =IF(P19<>1,"",IF(F19=0,0,I19))
B20: {=IF(A20="","",IF(COUNTIF(Companies!$A$6:$A$55,A20)<>1,"n.a.",INDEX(Companies!$C$6:$C$55,MATCH(A20,Companies!$A$6:$A$55,0))))} | F20: =IF(A20="","",COUNTIFS(Relationships!$A$6:$A$205,A20,Relationships!$U$6:$U$205,1)) | G20: =IF(A20="","",COUNTIFS(Relationships!$A$6:$A$205,A20,Relationships!$U$6:$U$205,1,Relationships!$C$6:$C$205,"Client")+COUNTIFS(Relationships!$A$6:$A$205,A20,Relationships!$U$6:$U$205,1,Relationships!$C$6:$C$205,"Client and partner")) | H20: =IF(A20="","",COUNTIFS(Relationships!$A$6:$A$205,A20,Relationships!$U$6:$U$205,1,Relationships!$C$6:$C$205,"Partner")+COUNTIFS(Relationships!$A$6:$A$205,A20,Relationships!$U$6:$U$205,1,Relationships!$C$6:$C$205,"Client and partner")) | I20: =IFERROR(__xludf.DUMMYFUNCTION("IF(A20="""","""",IF(F20=0,""n.a."",MEDIAN(FILTER(Relationships!$Q$6:$Q$205,Relationships!$A$6:$A$205=A20,Relationships!$U$6:$U$205=1))))"),"") | J20: =IF(A20="","",IF(OR(P20<>1,$B$8<>"Ready"),"n.a.",IF(F20=0,0,100*(COUNTIFS($P$14:$P$63,1,$F$14:$F$63,"<"&F20)+0.5*(COUNTIFS($P$14:$P$63,1,$F$14:$F$63,F20)-1))/($B$6-1)))) | K20: =IF(A20="","",IF(OR(P20<>1,$B$8<>"Ready"),"n.a.",IF(F20=0,0,100*(COUNTIFS($P$14:$P$63,1,$S$14:$S$63,"<"&I20)+0.5*(COUNTIFS($P$14:$P$63,1,$S$14:$S$63,I20)-1))/($B$6-1)))) | L20: =IF(A20="","",IF(OR(P20<>1,$B$8<>"Ready"),"n.a.",$G$5*J20+$G$6*K20)) | M20: =IF(A20="","",IF(NOT(ISNUMBER(L20)),"n.a.",1+COUNTIFS($P$14:$P$63,1,$L$14:$L$63,">"&L20))) | N20: =IF(A20="","",COUNTIFS(Relationships!$A$6:$A$205,A20,Relationships!$V$6:$V$205,1)) | O20: =IF(A20="","",IF(Q20<>1,"Outside cap universe",IF(R20<>1,"Duplicate network issuer",IF(C20<>"Yes","Review incomplete",IF(OR(NOT(ISNUMBER(D20)),D20>Rules!$B$6,Rules!$B$6-D20>Rules!$B$42,E20=""),"Check review date/log",IF(N20>0,"Resolve included records",IF($B$8<>"Ready",$B$8,IF(F20=0,"Reviewed: no qualifying ties","Ranked")))))))) | P20: =IF(A20="",0,IF(AND(Q20=1,R20=1,C20="Yes",ISNUMBER(D20),D20<=Rules!$B$6,Rules!$B$6-D20<=Rules!$B$42,E20<>"",N20=0),1,0)) -> 0 | Q20: {=IF(A20="",0,IF(COUNTIF(Companies!$A$6:$A$55,A20)<>1,0,IF(AND(INDEX(Companies!$R$6:$R$55,MATCH(A20,Companies!$A$6:$A$55,0))=1,INDEX(Companies!$I$6:$I$55,MATCH(A20,Companies!$A$6:$A$55,0))>=MAX(10,Rules!$B$22)),1,0)))} -> 0 | R20: =IF(A20="","",COUNTIF($A$14:$A$63,A20)) | S20: =IF(P20<>1,"",IF(F20=0,0,I20))
B21: {=IF(A21="","",IF(COUNTIF(Companies!$A$6:$A$55,A21)<>1,"n.a.",INDEX(Companies!$C$6:$C$55,MATCH(A21,Companies!$A$6:$A$55,0))))} | F21: =IF(A21="","",COUNTIFS(Relationships!$A$6:$A$205,A21,Relationships!$U$6:$U$205,1)) | G21: =IF(A21="","",COUNTIFS(Relationships!$A$6:$A$205,A21,Relationships!$U$6:$U$205,1,Relationships!$C$6:$C$205,"Client")+COUNTIFS(Relationships!$A$6:$A$205,A21,Relationships!$U$6:$U$205,1,Relationships!$C$6:$C$205,"Client and partner")) | H21: =IF(A21="","",COUNTIFS(Relationships!$A$6:$A$205,A21,Relationships!$U$6:$U$205,1,Relationships!$C$6:$C$205,"Partner")+COUNTIFS(Relationships!$A$6:$A$205,A21,Relationships!$U$6:$U$205,1,Relationships!$C$6:$C$205,"Client and partner")) | I21: =IFERROR(__xludf.DUMMYFUNCTION("IF(A21="""","""",IF(F21=0,""n.a."",MEDIAN(FILTER(Relationships!$Q$6:$Q$205,Relationships!$A$6:$A$205=A21,Relationships!$U$6:$U$205=1))))"),"") | J21: =IF(A21="","",IF(OR(P21<>1,$B$8<>"Ready"),"n.a.",IF(F21=0,0,100*(COUNTIFS($P$14:$P$63,1,$F$14:$F$63,"<"&F21)+0.5*(COUNTIFS($P$14:$P$63,1,$F$14:$F$63,F21)-1))/($B$6-1)))) | K21: =IF(A21="","",IF(OR(P21<>1,$B$8<>"Ready"),"n.a.",IF(F21=0,0,100*(COUNTIFS($P$14:$P$63,1,$S$14:$S$63,"<"&I21)+0.5*(COUNTIFS($P$14:$P$63,1,$S$14:$S$63,I21)-1))/($B$6-1)))) | L21: =IF(A21="","",IF(OR(P21<>1,$B$8<>"Ready"),"n.a.",$G$5*J21+$G$6*K21)) | M21: =IF(A21="","",IF(NOT(ISNUMBER(L21)),"n.a.",1+COUNTIFS($P$14:$P$63,1,$L$14:$L$63,">"&L21))) | N21: =IF(A21="","",COUNTIFS(Relationships!$A$6:$A$205,A21,Relationships!$V$6:$V$205,1)) | O21: =IF(A21="","",IF(Q21<>1,"Outside cap universe",IF(R21<>1,"Duplicate network issuer",IF(C21<>"Yes","Review incomplete",IF(OR(NOT(ISNUMBER(D21)),D21>Rules!$B$6,Rules!$B$6-D21>Rules!$B$42,E21=""),"Check review date/log",IF(N21>0,"Resolve included records",IF($B$8<>"Ready",$B$8,IF(F21=0,"Reviewed: no qualifying ties","Ranked")))))))) | P21: =IF(A21="",0,IF(AND(Q21=1,R21=1,C21="Yes",ISNUMBER(D21),D21<=Rules!$B$6,Rules!$B$6-D21<=Rules!$B$42,E21<>"",N21=0),1,0)) -> 0 | Q21: {=IF(A21="",0,IF(COUNTIF(Companies!$A$6:$A$55,A21)<>1,0,IF(AND(INDEX(Companies!$R$6:$R$55,MATCH(A21,Companies!$A$6:$A$55,0))=1,INDEX(Companies!$I$6:$I$55,MATCH(A21,Companies!$A$6:$A$55,0))>=MAX(10,Rules!$B$22)),1,0)))} -> 0 | R21: =IF(A21="","",COUNTIF($A$14:$A$63,A21)) | S21: =IF(P21<>1,"",IF(F21=0,0,I21))
B22: {=IF(A22="","",IF(COUNTIF(Companies!$A$6:$A$55,A22)<>1,"n.a.",INDEX(Companies!$C$6:$C$55,MATCH(A22,Companies!$A$6:$A$55,0))))} | F22: =IF(A22="","",COUNTIFS(Relationships!$A$6:$A$205,A22,Relationships!$U$6:$U$205,1)) | G22: =IF(A22="","",COUNTIFS(Relationships!$A$6:$A$205,A22,Relationships!$U$6:$U$205,1,Relationships!$C$6:$C$205,"Client")+COUNTIFS(Relationships!$A$6:$A$205,A22,Relationships!$U$6:$U$205,1,Relationships!$C$6:$C$205,"Client and partner")) | H22: =IF(A22="","",COUNTIFS(Relationships!$A$6:$A$205,A22,Relationships!$U$6:$U$205,1,Relationships!$C$6:$C$205,"Partner")+COUNTIFS(Relationships!$A$6:$A$205,A22,Relationships!$U$6:$U$205,1,Relationships!$C$6:$C$205,"Client and partner")) | I22: =IFERROR(__xludf.DUMMYFUNCTION("IF(A22="""","""",IF(F22=0,""n.a."",MEDIAN(FILTER(Relationships!$Q$6:$Q$205,Relationships!$A$6:$A$205=A22,Relationships!$U$6:$U$205=1))))"),"") | J22: =IF(A22="","",IF(OR(P22<>1,$B$8<>"Ready"),"n.a.",IF(F22=0,0,100*(COUNTIFS($P$14:$P$63,1,$F$14:$F$63,"<"&F22)+0.5*(COUNTIFS($P$14:$P$63,1,$F$14:$F$63,F22)-1))/($B$6-1)))) | K22: =IF(A22="","",IF(OR(P22<>1,$B$8<>"Ready"),"n.a.",IF(F22=0,0,100*(COUNTIFS($P$14:$P$63,1,$S$14:$S$63,"<"&I22)+0.5*(COUNTIFS($P$14:$P$63,1,$S$14:$S$63,I22)-1))/($B$6-1)))) | L22: =IF(A22="","",IF(OR(P22<>1,$B$8<>"Ready"),"n.a.",$G$5*J22+$G$6*K22)) | M22: =IF(A22="","",IF(NOT(ISNUMBER(L22)),"n.a.",1+COUNTIFS($P$14:$P$63,1,$L$14:$L$63,">"&L22))) | N22: =IF(A22="","",COUNTIFS(Relationships!$A$6:$A$205,A22,Relationships!$V$6:$V$205,1)) | O22: =IF(A22="","",IF(Q22<>1,"Outside cap universe",IF(R22<>1,"Duplicate network issuer",IF(C22<>"Yes","Review incomplete",IF(OR(NOT(ISNUMBER(D22)),D22>Rules!$B$6,Rules!$B$6-D22>Rules!$B$42,E22=""),"Check review date/log",IF(N22>0,"Resolve included records",IF($B$8<>"Ready",$B$8,IF(F22=0,"Reviewed: no qualifying ties","Ranked")))))))) | P22: =IF(A22="",0,IF(AND(Q22=1,R22=1,C22="Yes",ISNUMBER(D22),D22<=Rules!$B$6,Rules!$B$6-D22<=Rules!$B$42,E22<>"",N22=0),1,0)) -> 0 | Q22: {=IF(A22="",0,IF(COUNTIF(Companies!$A$6:$A$55,A22)<>1,0,IF(AND(INDEX(Companies!$R$6:$R$55,MATCH(A22,Companies!$A$6:$A$55,0))=1,INDEX(Companies!$I$6:$I$55,MATCH(A22,Companies!$A$6:$A$55,0))>=MAX(10,Rules!$B$22)),1,0)))} -> 0 | R22: =IF(A22="","",COUNTIF($A$14:$A$63,A22)) | S22: =IF(P22<>1,"",IF(F22=0,0,I22))
